<robot name="test_robot">
  <link name="base_link"/>

  <joint name="turret_base_joint" type="fixed">
    <origin rpy="0 0 0" xyz="0 0 0.6"/>
    <parent link="base_link"/>
    <child  link="turret_base_link"/>
  </joint>
  <link name="turret_base_link"/>

  <joint name="turret_tip_joint" type="floating">
    <parent link="turret_base_link"/>
    <child  link="turret_tip_link"/>
  </joint>
  <link name="turret_tip_link"/>

  <joint name="head_camera_joint" type="fixed">
    <origin rpy="0 0 0" xyz="0.03 0 0"/>
    <parent link="turret_tip_link"/>
    <child  link="head_camera_link"/>
  </joint>
  <link name="head_camera_link"/>

  <joint name="front_laser_joint" type="fixed">
    <origin rpy="0 0 0" xyz="0.141 0 0"/>
    <parent link="base_link"/>
    <child  link="front_laser_link"/>
  </joint>
  <link name="front_laser_link"/>

</robot>
